----------stdout----------
" 1>   meta_datetime  ... scores_90_weird_metric\n 1> 0   08-03 21:50  ...                      0\n 1> \n 1> [1 rows x 219 columns]\n 1> multiprocessing.pool.RemoteTraceback: \n 1> \"\"\"\n 1> Traceback (most recent call last):\n 1>   File \"/usr/local/lib/python3.7/multiprocessing/pool.py\", line 121, in worker\n 1>     result = (True, func(*args, **kwds))\n 1>   File \"/usr/local/lib/python3.7/multiprocessing/pool.py\", line 44, in mapstar\n 1>     return list(map(*args))\n 1>   File \"/usr/local/lib/python3.7/site-packages/evolutionary_search/cv.py\", line 104, in _evalFunction\n 1>     error_score=error_score)[0]\n 1>   File \"/usr/local/lib/python3.7/site-packages/sklearn/model_selection/_validation.py\", line 531, in _fit_and_score\n 1>     estimator.fit(X_train, y_train, **fit_params)\n 1>   File \"/job/HyperParamsOpti.py\", line 90, in fit\n 1>     self._model_.learn()\n 1>   File \"/job/CuteNet.py\", line 256, in learn\n 1>     self.eval()\n 1>   File \"/job/CuteNet.py\", line 332, in eval\n 1>     self.save()\n 1>   File \"/job/CuteNet.py\", line 409, in save\n 1>     with open(name + \".json\", \"w+\") as f:\n 1> FileNotFoundError: [Errno 2] No such file or directory: 'model_cache/319Points_199.13WinRatio_200Episodes_08-03 20:59.json'\n 1> \"\"\"\n 1> \n 1> The above exception was the direct cause of the following exception:\n 1> \n 1> Traceback (most recent call last):\n 1>   File \"Genetic_HP_Opti.py\", line 30, in <module>\n 1>     ret = cv.fit(X, y)\n 1>   File \"/usr/local/lib/python3.7/site-packages/evolutionary_search/cv.py\", line 364, in fit\n 1>     self._fit(X, y, possible_params)\n 1>   File \"/usr/local/lib/python3.7/site-packages/evolutionary_search/cv.py\", line 454, in _fit\n 1>     halloffame=hof, verbose=self.verbose)\n 1>   File \"/usr/local/lib/python3.7/site-packages/deap/algorithms.py\", line 150, in eaSimple\n 1>     fitnesses = toolbox.map(toolbox.evaluate, invalid_ind)\n 1>   File \"/usr/local/lib/python3.7/multiprocessing/pool.py\", line 268, in map\n 1>     return self._map_async(func, iterable, mapstar, chunksize).get()\n 1>   File \"/usr/local/lib/python3.7/multiprocessing/pool.py\", line 657, in get\n 1>     raise self._value\n 1> FileNotFoundError: [Errno 2] No such file or directory: 'model_cache/319Points_199.13WinRatio_200Episodes_08-03 20:59.json'"
--------------------------

